// const p = require('process');

process.on('beforeExit', () => {
    console.log('el proceso va a terminar');
});

process.on('exit', () => {
    console.log('Ale, el proceso acabÃ³');
    setTimeout(() => {
        console.log('Esto no se va a ver nunca');
    }, 0);
});

setTimeout(() => {
    console.log('Esto se va a ver');
}, 0);

process.on('uncaughtException', (err, origen) => {
    console.error('Vaya se nos ha olvidado capturar un error');
    setTimeout(() => {
        console.log('Esto viene desde las excepciones');
    }, 0);
});


funcionQueNoExiste();

console.log('Esto si el error no se recoje, no sale');
